I'm sorry, but an uncaught exception occurred.

While running game code:
  File "game/script.rpy", line 88, in script
    "The Enemy attacks for [0] damage!"
IndexError: tuple index out of range

-- Full Traceback ------------------------------------------------------------

Full traceback:
  File "game/script.rpy", line 88, in script
    "The Enemy attacks for [0] damage!"
  File "C:\Renpy\renpy-7.3.5-sdk\renpy\ast.py", line 921, in execute
    renpy.exports.say(who, what, *args, **kwargs)
  File "C:\Renpy\renpy-7.3.5-sdk\renpy\exports.py", line 1373, in say
    who(what, *args, **kwargs)
  File "C:\Renpy\renpy-7.3.5-sdk\renpy\character.py", line 1253, in __call__
    what = self.prefix_suffix("what", self.what_prefix, what, self.what_suffix)
  File "C:\Renpy\renpy-7.3.5-sdk\renpy\character.py", line 1172, in prefix_suffix
    return (sub(prefix) + sub(body) + sub(suffix))
  File "C:\Renpy\renpy-7.3.5-sdk\renpy\character.py", line 1152, in sub
    return renpy.substitutions.substitute(s, scope=scope, force=force, translate=translate)[0]
  File "C:\Renpy\renpy-7.3.5-sdk\renpy\substitutions.py", line 278, in substitute
    s = formatter.vformat(s, (), kwargs) # type: ignore
  File "/home/tom/ab/renpy-build/tmp/install.linux-x86_64/lib/python3.9/string.py", line 165, in vformat
  File "/home/tom/ab/renpy-build/tmp/install.linux-x86_64/lib/python3.9/string.py", line 205, in _vformat
  File "C:\Renpy\renpy-7.3.5-sdk\renpy\substitutions.py", line 168, in get_field
    obj, arg_used = super(Formatter, self).get_field(field_name, args, kwargs)
  File "/home/tom/ab/renpy-build/tmp/install.linux-x86_64/lib/python3.9/string.py", line 270, in get_field
  File "/home/tom/ab/renpy-build/tmp/install.linux-x86_64/lib/python3.9/string.py", line 225, in get_value
IndexError: tuple index out of range

Windows-10-10.0.19044 AMD64
Ren'Py 8.0.3.22090809
Test Turn Based combat 1.0
Mon Mar 20 20:26:36 2023
